<?xml version="1.0" encoding="UTF-8"?>
<sdf version='1.9'>
  <model name='h600_base'>
    <pose>0 0 .24 0 0 0</pose>
    <self_collide>false</self_collide>
    <static>false</static>
    <link name="base_link">
      <inertial>
        <mass>2.5</mass>
        <inertia>
          <ixx>0.035</ixx>
          <ixy>0</ixy>
          <ixz>0</ixz>
          <iyy>0.035</iyy>
          <iyz>0</iyz>
          <izz>0.06</izz>
        </inertia>
      </inertial>
      <gravity>true</gravity>
      <velocity_decay/>
      <!-- Central body - hexagonal frame representation -->
      <visual name="base_link_visual">
        <pose>0 0 0 0 0 0</pose>
        <geometry>
          <cylinder>
            <radius>0.12</radius>
            <length>0.05</length>
          </cylinder>
        </geometry>
        <material>
          <ambient>0.2 0.2 0.2 1</ambient>
          <diffuse>0.3 0.3 0.3 1</diffuse>
        </material>
      </visual>
      <!-- Arms - 6 arms at 60 degree intervals -->
      <!-- Arm 0: Front right (30 deg) -->
      <visual name="arm_0">
        <pose>0.095 -0.055 0 0 0 -0.5236</pose>
        <geometry>
          <box>
            <size>0.24 0.02 0.015</size>
          </box>
        </geometry>
        <material>
          <ambient>0.1 0.1 0.1 1</ambient>
          <diffuse>0.2 0.2 0.2 1</diffuse>
        </material>
      </visual>
      <!-- Arm 1: Rear left (150 deg) -->
      <visual name="arm_1">
        <pose>-0.095 0.055 0 0 0 -0.5236</pose>
        <geometry>
          <box>
            <size>0.24 0.02 0.015</size>
          </box>
        </geometry>
        <material>
          <ambient>0.1 0.1 0.1 1</ambient>
          <diffuse>0.2 0.2 0.2 1</diffuse>
        </material>
      </visual>
      <!-- Arm 2: Front left (150 deg mirror) -->
      <visual name="arm_2">
        <pose>0.095 0.055 0 0 0 0.5236</pose>
        <geometry>
          <box>
            <size>0.24 0.02 0.015</size>
          </box>
        </geometry>
        <material>
          <ambient>0.1 0.1 0.1 1</ambient>
          <diffuse>0.2 0.2 0.2 1</diffuse>
        </material>
      </visual>
      <!-- Arm 3: Rear right (-150 deg) -->
      <visual name="arm_3">
        <pose>-0.095 -0.055 0 0 0 0.5236</pose>
        <geometry>
          <box>
            <size>0.24 0.02 0.015</size>
          </box>
        </geometry>
        <material>
          <ambient>0.1 0.1 0.1 1</ambient>
          <diffuse>0.2 0.2 0.2 1</diffuse>
        </material>
      </visual>
      <!-- Arm 4: Right (90 deg) -->
      <visual name="arm_4">
        <pose>0 -0.11 0 0 0 1.5708</pose>
        <geometry>
          <box>
            <size>0.24 0.02 0.015</size>
          </box>
        </geometry>
        <material>
          <ambient>0.1 0.1 0.1 1</ambient>
          <diffuse>0.2 0.2 0.2 1</diffuse>
        </material>
      </visual>
      <!-- Arm 5: Left (-90 deg) -->
      <visual name="arm_5">
        <pose>0 0.11 0 0 0 1.5708</pose>
        <geometry>
          <box>
            <size>0.24 0.02 0.015</size>
          </box>
        </geometry>
        <material>
          <ambient>0.1 0.1 0.1 1</ambient>
          <diffuse>0.2 0.2 0.2 1</diffuse>
        </material>
      </visual>
      <!-- Motor bases -->
      <visual name="motor_base_0">
        <pose>0.19 -0.11 0.025 0 0 0</pose>
        <geometry>
          <cylinder>
            <radius>0.025</radius>
            <length>0.02</length>
          </cylinder>
        </geometry>
        <material>
          <ambient>0.3 0.3 0.3 1</ambient>
          <diffuse>0.4 0.4 0.4 1</diffuse>
        </material>
      </visual>
      <visual name="motor_base_1">
        <pose>-0.19 0.11 0.025 0 0 0</pose>
        <geometry>
          <cylinder>
            <radius>0.025</radius>
            <length>0.02</length>
          </cylinder>
        </geometry>
        <material>
          <ambient>0.3 0.3 0.3 1</ambient>
          <diffuse>0.4 0.4 0.4 1</diffuse>
        </material>
      </visual>
      <visual name="motor_base_2">
        <pose>0.19 0.11 0.025 0 0 0</pose>
        <geometry>
          <cylinder>
            <radius>0.025</radius>
            <length>0.02</length>
          </cylinder>
        </geometry>
        <material>
          <ambient>0.3 0.3 0.3 1</ambient>
          <diffuse>0.4 0.4 0.4 1</diffuse>
        </material>
      </visual>
      <visual name="motor_base_3">
        <pose>-0.19 -0.11 0.025 0 0 0</pose>
        <geometry>
          <cylinder>
            <radius>0.025</radius>
            <length>0.02</length>
          </cylinder>
        </geometry>
        <material>
          <ambient>0.3 0.3 0.3 1</ambient>
          <diffuse>0.4 0.4 0.4 1</diffuse>
        </material>
      </visual>
      <visual name="motor_base_4">
        <pose>0 -0.22 0.025 0 0 0</pose>
        <geometry>
          <cylinder>
            <radius>0.025</radius>
            <length>0.02</length>
          </cylinder>
        </geometry>
        <material>
          <ambient>0.3 0.3 0.3 1</ambient>
          <diffuse>0.4 0.4 0.4 1</diffuse>
        </material>
      </visual>
      <visual name="motor_base_5">
        <pose>0 0.22 0.025 0 0 0</pose>
        <geometry>
          <cylinder>
            <radius>0.025</radius>
            <length>0.02</length>
          </cylinder>
        </geometry>
        <material>
          <ambient>0.3 0.3 0.3 1</ambient>
          <diffuse>0.4 0.4 0.4 1</diffuse>
        </material>
      </visual>
      <!-- Front direction indicator (red) -->
      <visual name="front_indicator">
        <pose>0.08 0 0.03 0 0 0</pose>
        <geometry>
          <box>
            <size>0.04 0.02 0.01</size>
          </box>
        </geometry>
        <material>
          <ambient>1 0 0 1</ambient>
          <diffuse>1 0 0 1</diffuse>
        </material>
      </visual>
      <!-- Landing gear legs - wider stance -->
      <visual name="landing_leg_1">
        <pose>0.15 -0.15 -0.14 0.3 0 0</pose>
        <geometry>
          <cylinder>
            <radius>0.008</radius>
            <length>0.25</length>
          </cylinder>
        </geometry>
        <material>
          <ambient>0.1 0.1 0.1 1</ambient>
          <diffuse>0.15 0.15 0.15 1</diffuse>
        </material>
      </visual>
      <visual name="landing_leg_2">
        <pose>0.15 0.15 -0.14 -0.3 0 0</pose>
        <geometry>
          <cylinder>
            <radius>0.008</radius>
            <length>0.25</length>
          </cylinder>
        </geometry>
        <material>
          <ambient>0.1 0.1 0.1 1</ambient>
          <diffuse>0.15 0.15 0.15 1</diffuse>
        </material>
      </visual>
      <visual name="landing_leg_3">
        <pose>-0.15 -0.15 -0.14 0.3 0 0</pose>
        <geometry>
          <cylinder>
            <radius>0.008</radius>
            <length>0.25</length>
          </cylinder>
        </geometry>
        <material>
          <ambient>0.1 0.1 0.1 1</ambient>
          <diffuse>0.15 0.15 0.15 1</diffuse>
        </material>
      </visual>
      <visual name="landing_leg_4">
        <pose>-0.15 0.15 -0.14 -0.3 0 0</pose>
        <geometry>
          <cylinder>
            <radius>0.008</radius>
            <length>0.25</length>
          </cylinder>
        </geometry>
        <material>
          <ambient>0.1 0.1 0.1 1</ambient>
          <diffuse>0.15 0.15 0.15 1</diffuse>
        </material>
      </visual>
      <!-- Landing skids - wider spread -->
      <visual name="landing_skid_front">
        <pose>0.15 0 -0.25 0 1.5708 0</pose>
        <geometry>
          <cylinder>
            <radius>0.01</radius>
            <length>0.35</length>
          </cylinder>
        </geometry>
        <material>
          <ambient>0.1 0.1 0.1 1</ambient>
          <diffuse>0.15 0.15 0.15 1</diffuse>
        </material>
      </visual>
      <visual name="landing_skid_rear">
        <pose>-0.15 0 -0.25 0 1.5708 0</pose>
        <geometry>
          <cylinder>
            <radius>0.01</radius>
            <length>0.35</length>
          </cylinder>
        </geometry>
        <material>
          <ambient>0.1 0.1 0.1 1</ambient>
          <diffuse>0.15 0.15 0.15 1</diffuse>
        </material>
      </visual>
      <!-- Collision geometry -->
      <collision name="base_link_collision">
        <pose>0 0 0 0 0 0</pose>
        <geometry>
          <cylinder>
            <radius>0.25</radius>
            <length>0.05</length>
          </cylinder>
        </geometry>
        <surface>
          <contact>
            <ode>
              <min_depth>0.001</min_depth>
              <max_vel>0</max_vel>
            </ode>
          </contact>
          <friction>
            <ode/>
          </friction>
        </surface>
      </collision>
      <!-- Landing leg collisions - 4 corner contact points (skid collisions removed to prevent interpenetration) -->
      <collision name="landing_leg_collision_1">
        <pose>0.15 -0.15 -0.14 0.3 0 0</pose>
        <geometry>
          <cylinder>
            <radius>0.01</radius>
            <length>0.25</length>
          </cylinder>
        </geometry>
        <surface>
          <contact>
            <ode>
              <min_depth>0.001</min_depth>
              <max_vel>0</max_vel>
            </ode>
          </contact>
          <friction>
            <ode/>
          </friction>
        </surface>
      </collision>
      <collision name="landing_leg_collision_2">
        <pose>0.15 0.15 -0.14 -0.3 0 0</pose>
        <geometry>
          <cylinder>
            <radius>0.01</radius>
            <length>0.25</length>
          </cylinder>
        </geometry>
        <surface>
          <contact>
            <ode>
              <min_depth>0.001</min_depth>
              <max_vel>0</max_vel>
            </ode>
          </contact>
          <friction>
            <ode/>
          </friction>
        </surface>
      </collision>
      <collision name="landing_leg_collision_3">
        <pose>-0.15 -0.15 -0.14 0.3 0 0</pose>
        <geometry>
          <cylinder>
            <radius>0.01</radius>
            <length>0.25</length>
          </cylinder>
        </geometry>
        <surface>
          <contact>
            <ode>
              <min_depth>0.001</min_depth>
              <max_vel>0</max_vel>
            </ode>
          </contact>
          <friction>
            <ode/>
          </friction>
        </surface>
      </collision>
      <collision name="landing_leg_collision_4">
        <pose>-0.15 0.15 -0.14 -0.3 0 0</pose>
        <geometry>
          <cylinder>
            <radius>0.01</radius>
            <length>0.25</length>
          </cylinder>
        </geometry>
        <surface>
          <contact>
            <ode>
              <min_depth>0.001</min_depth>
              <max_vel>0</max_vel>
            </ode>
          </contact>
          <friction>
            <ode/>
          </friction>
        </surface>
      </collision>
      <!-- Sensors -->
      <sensor name="air_pressure_sensor" type="air_pressure">
        <always_on>1</always_on>
        <update_rate>50</update_rate>
        <air_pressure>
          <pressure>
            <noise type="gaussian">
              <mean>0</mean>
              <stddev>3</stddev>
            </noise>
          </pressure>
        </air_pressure>
      </sensor>
      <sensor name="magnetometer_sensor" type="magnetometer">
        <always_on>1</always_on>
        <update_rate>100</update_rate>
        <magnetometer>
          <x>
            <noise type="gaussian">
              <stddev>0.0001</stddev>
            </noise>
          </x>
          <y>
            <noise type="gaussian">
              <stddev>0.0001</stddev>
            </noise>
          </y>
          <z>
            <noise type="gaussian">
              <stddev>0.0001</stddev>
            </noise>
          </z>
        </magnetometer>
      </sensor>
      <sensor name="imu_sensor" type="imu">
        <always_on>1</always_on>
        <update_rate>250</update_rate>
        <imu>
          <angular_velocity>
            <x>
              <noise type="gaussian">
                <mean>0.0</mean>
                <stddev>0.0008726646</stddev>
              </noise>
            </x>
            <y>
              <noise type="gaussian">
                <mean>0.0</mean>
                <stddev>0.0008726646</stddev>
              </noise>
            </y>
            <z>
              <noise type="gaussian">
                <mean>0.0</mean>
                <stddev>0.0008726646</stddev>
              </noise>
            </z>
          </angular_velocity>
          <linear_acceleration>
            <x>
              <noise type="gaussian">
                <mean>0.0</mean>
                <stddev>0.00637</stddev>
              </noise>
            </x>
            <y>
              <noise type="gaussian">
                <mean>0.0</mean>
                <stddev>0.00637</stddev>
              </noise>
            </y>
            <z>
              <noise type="gaussian">
                <mean>0.0</mean>
                <stddev>0.00686</stddev>
              </noise>
            </z>
          </linear_acceleration>
        </imu>
      </sensor>
      <sensor name="navsat_sensor" type="navsat">
        <always_on>1</always_on>
        <update_rate>30</update_rate>
      </sensor>
    </link>

    <!-- Rotor 0: Front right - CCW -->
    <link name="rotor_0">
      <gravity>true</gravity>
      <self_collide>false</self_collide>
      <velocity_decay/>
      <pose>0.19 -0.11 0.06 0 0 0</pose>
      <inertial>
          <mass>0.016076923076923075</mass>
          <inertia>
            <ixx>3.8464910483993325e-07</ixx>
            <ixy>0</ixy>
            <ixz>0</ixz>
            <iyy>2.6115851691700804e-05</iyy>
            <iyz>0</iyz>
            <izz>2.649858234714004e-05</izz>
          </inertia>
        </inertial>
      <visual name="rotor_0_visual">
        <pose>0 0 0 0 0 0</pose>
        <geometry>
          <cylinder>
            <radius>0.127</radius>
            <length>0.005</length>
          </cylinder>
        </geometry>
        <material>
          <ambient>0.2 0.2 0.2 0.8</ambient>
          <diffuse>0.3 0.3 0.3 0.8</diffuse>
        </material>
      </visual>
      <visual name="rotor_0_motor_bell">
        <pose>0 0 -0.015 0 0 0</pose>
        <geometry>
          <cylinder>
            <radius>0.018</radius>
            <length>0.025</length>
          </cylinder>
        </geometry>
        <material>
          <ambient>0.4 0.4 0.4 1</ambient>
          <diffuse>0.5 0.5 0.5 1</diffuse>
        </material>
      </visual>
      <collision name="rotor_0_collision">
        <pose>0 0 0 0 0 0</pose>
        <geometry>
          <cylinder>
            <radius>0.127</radius>
            <length>0.005</length>
          </cylinder>
        </geometry>
      </collision>
    </link>
    <joint name="rotor_0_joint" type="revolute">
      <parent>base_link</parent>
      <child>rotor_0</child>
      <axis>
        <xyz>0 0 1</xyz>
        <limit>
          <lower>-1e+16</lower>
          <upper>1e+16</upper>
        </limit>
        <dynamics>
          <spring_reference>0</spring_reference>
          <spring_stiffness>0</spring_stiffness>
        </dynamics>
      </axis>
    </joint>

    <!-- Rotor 1: Rear left - CCW -->
    <link name="rotor_1">
      <gravity>true</gravity>
      <self_collide>false</self_collide>
      <velocity_decay/>
      <pose>-0.19 0.11 0.06 0 0 0</pose>
      <inertial>
          <mass>0.016076923076923075</mass>
          <inertia>
            <ixx>3.8464910483993325e-07</ixx>
            <ixy>0</ixy>
            <ixz>0</ixz>
            <iyy>2.6115851691700804e-05</iyy>
            <iyz>0</iyz>
            <izz>2.649858234714004e-05</izz>
          </inertia>
        </inertial>
      <visual name="rotor_1_visual">
        <pose>0 0 0 0 0 0</pose>
        <geometry>
          <cylinder>
            <radius>0.127</radius>
            <length>0.005</length>
          </cylinder>
        </geometry>
        <material>
          <ambient>0.2 0.2 0.2 0.8</ambient>
          <diffuse>0.3 0.3 0.3 0.8</diffuse>
        </material>
      </visual>
      <visual name="rotor_1_motor_bell">
        <pose>0 0 -0.015 0 0 0</pose>
        <geometry>
          <cylinder>
            <radius>0.018</radius>
            <length>0.025</length>
          </cylinder>
        </geometry>
        <material>
          <ambient>0.4 0.4 0.4 1</ambient>
          <diffuse>0.5 0.5 0.5 1</diffuse>
        </material>
      </visual>
      <collision name="rotor_1_collision">
        <pose>0 0 0 0 0 0</pose>
        <geometry>
          <cylinder>
            <radius>0.127</radius>
            <length>0.005</length>
          </cylinder>
        </geometry>
      </collision>
    </link>
    <joint name="rotor_1_joint" type="revolute">
      <parent>base_link</parent>
      <child>rotor_1</child>
      <axis>
        <xyz>0 0 1</xyz>
        <limit>
          <lower>-1e+16</lower>
          <upper>1e+16</upper>
        </limit>
        <dynamics>
          <spring_reference>0</spring_reference>
          <spring_stiffness>0</spring_stiffness>
        </dynamics>
      </axis>
    </joint>

    <!-- Rotor 2: Front left - CW -->
    <link name="rotor_2">
      <gravity>true</gravity>
      <self_collide>false</self_collide>
      <velocity_decay/>
      <pose>0.19 0.11 0.06 0 0 0</pose>
      <inertial>
          <mass>0.016076923076923075</mass>
          <inertia>
            <ixx>3.8464910483993325e-07</ixx>
            <ixy>0</ixy>
            <ixz>0</ixz>
            <iyy>2.6115851691700804e-05</iyy>
            <iyz>0</iyz>
            <izz>2.649858234714004e-05</izz>
          </inertia>
        </inertial>
      <visual name="rotor_2_visual">
        <pose>0 0 0 0 0 0</pose>
        <geometry>
          <cylinder>
            <radius>0.127</radius>
            <length>0.005</length>
          </cylinder>
        </geometry>
        <material>
          <ambient>0.2 0.2 0.2 0.8</ambient>
          <diffuse>0.3 0.3 0.3 0.8</diffuse>
        </material>
      </visual>
      <visual name="rotor_2_motor_bell">
        <pose>0 0 -0.015 0 0 0</pose>
        <geometry>
          <cylinder>
            <radius>0.018</radius>
            <length>0.025</length>
          </cylinder>
        </geometry>
        <material>
          <ambient>0.4 0.4 0.4 1</ambient>
          <diffuse>0.5 0.5 0.5 1</diffuse>
        </material>
      </visual>
      <collision name="rotor_2_collision">
        <pose>0 0 0 0 0 0</pose>
        <geometry>
          <cylinder>
            <radius>0.127</radius>
            <length>0.005</length>
          </cylinder>
        </geometry>
      </collision>
    </link>
    <joint name="rotor_2_joint" type="revolute">
      <parent>base_link</parent>
      <child>rotor_2</child>
      <axis>
        <xyz>0 0 1</xyz>
        <limit>
          <lower>-1e+16</lower>
          <upper>1e+16</upper>
        </limit>
        <dynamics>
          <spring_reference>0</spring_reference>
          <spring_stiffness>0</spring_stiffness>
        </dynamics>
      </axis>
    </joint>

    <!-- Rotor 3: Rear right - CW -->
    <link name="rotor_3">
      <gravity>true</gravity>
      <self_collide>false</self_collide>
      <velocity_decay/>
      <pose>-0.19 -0.11 0.06 0 0 0</pose>
      <inertial>
          <mass>0.016076923076923075</mass>
          <inertia>
            <ixx>3.8464910483993325e-07</ixx>
            <ixy>0</ixy>
            <ixz>0</ixz>
            <iyy>2.6115851691700804e-05</iyy>
            <iyz>0</iyz>
            <izz>2.649858234714004e-05</izz>
          </inertia>
        </inertial>
      <visual name="rotor_3_visual">
        <pose>0 0 0 0 0 0</pose>
        <geometry>
          <cylinder>
            <radius>0.127</radius>
            <length>0.005</length>
          </cylinder>
        </geometry>
        <material>
          <ambient>0.2 0.2 0.2 0.8</ambient>
          <diffuse>0.3 0.3 0.3 0.8</diffuse>
        </material>
      </visual>
      <visual name="rotor_3_motor_bell">
        <pose>0 0 -0.015 0 0 0</pose>
        <geometry>
          <cylinder>
            <radius>0.018</radius>
            <length>0.025</length>
          </cylinder>
        </geometry>
        <material>
          <ambient>0.4 0.4 0.4 1</ambient>
          <diffuse>0.5 0.5 0.5 1</diffuse>
        </material>
      </visual>
      <collision name="rotor_3_collision">
        <pose>0 0 0 0 0 0</pose>
        <geometry>
          <cylinder>
            <radius>0.127</radius>
            <length>0.005</length>
          </cylinder>
        </geometry>
      </collision>
    </link>
    <joint name="rotor_3_joint" type="revolute">
      <parent>base_link</parent>
      <child>rotor_3</child>
      <axis>
        <xyz>0 0 1</xyz>
        <limit>
          <lower>-1e+16</lower>
          <upper>1e+16</upper>
        </limit>
        <dynamics>
          <spring_reference>0</spring_reference>
          <spring_stiffness>0</spring_stiffness>
        </dynamics>
      </axis>
    </joint>

    <!-- Rotor 4: Right - CCW -->
    <link name="rotor_4">
      <gravity>true</gravity>
      <self_collide>false</self_collide>
      <velocity_decay/>
      <pose>0 -0.22 0.06 0 0 0</pose>
      <inertial>
          <mass>0.016076923076923075</mass>
          <inertia>
            <ixx>3.8464910483993325e-07</ixx>
            <ixy>0</ixy>
            <ixz>0</ixz>
            <iyy>2.6115851691700804e-05</iyy>
            <iyz>0</iyz>
            <izz>2.649858234714004e-05</izz>
          </inertia>
        </inertial>
      <visual name="rotor_4_visual">
        <pose>0 0 0 0 0 0</pose>
        <geometry>
          <cylinder>
            <radius>0.127</radius>
            <length>0.005</length>
          </cylinder>
        </geometry>
        <material>
          <ambient>0.2 0.2 0.2 0.8</ambient>
          <diffuse>0.3 0.3 0.3 0.8</diffuse>
        </material>
      </visual>
      <visual name="rotor_4_motor_bell">
        <pose>0 0 -0.015 0 0 0</pose>
        <geometry>
          <cylinder>
            <radius>0.018</radius>
            <length>0.025</length>
          </cylinder>
        </geometry>
        <material>
          <ambient>0.4 0.4 0.4 1</ambient>
          <diffuse>0.5 0.5 0.5 1</diffuse>
        </material>
      </visual>
      <collision name="rotor_4_collision">
        <pose>0 0 0 0 0 0</pose>
        <geometry>
          <cylinder>
            <radius>0.127</radius>
            <length>0.005</length>
          </cylinder>
        </geometry>
      </collision>
    </link>
    <joint name="rotor_4_joint" type="revolute">
      <parent>base_link</parent>
      <child>rotor_4</child>
      <axis>
        <xyz>0 0 1</xyz>
        <limit>
          <lower>-1e+16</lower>
          <upper>1e+16</upper>
        </limit>
        <dynamics>
          <spring_reference>0</spring_reference>
          <spring_stiffness>0</spring_stiffness>
        </dynamics>
      </axis>
    </joint>

    <!-- Rotor 5: Left - CW -->
    <link name="rotor_5">
      <gravity>true</gravity>
      <self_collide>false</self_collide>
      <velocity_decay/>
      <pose>0 0.22 0.06 0 0 0</pose>
      <inertial>
          <mass>0.016076923076923075</mass>
          <inertia>
            <ixx>3.8464910483993325e-07</ixx>
            <ixy>0</ixy>
            <ixz>0</ixz>
            <iyy>2.6115851691700804e-05</iyy>
            <iyz>0</iyz>
            <izz>2.649858234714004e-05</izz>
          </inertia>
        </inertial>
      <visual name="rotor_5_visual">
        <pose>0 0 0 0 0 0</pose>
        <geometry>
          <cylinder>
            <radius>0.127</radius>
            <length>0.005</length>
          </cylinder>
        </geometry>
        <material>
          <ambient>0.2 0.2 0.2 0.8</ambient>
          <diffuse>0.3 0.3 0.3 0.8</diffuse>
        </material>
      </visual>
      <visual name="rotor_5_motor_bell">
        <pose>0 0 -0.015 0 0 0</pose>
        <geometry>
          <cylinder>
            <radius>0.018</radius>
            <length>0.025</length>
          </cylinder>
        </geometry>
        <material>
          <ambient>0.4 0.4 0.4 1</ambient>
          <diffuse>0.5 0.5 0.5 1</diffuse>
        </material>
      </visual>
      <collision name="rotor_5_collision">
        <pose>0 0 0 0 0 0</pose>
        <geometry>
          <cylinder>
            <radius>0.127</radius>
            <length>0.005</length>
          </cylinder>
        </geometry>
      </collision>
    </link>
    <joint name="rotor_5_joint" type="revolute">
      <parent>base_link</parent>
      <child>rotor_5</child>
      <axis>
        <xyz>0 0 1</xyz>
        <limit>
          <lower>-1e+16</lower>
          <upper>1e+16</upper>
        </limit>
        <dynamics>
          <spring_reference>0</spring_reference>
          <spring_stiffness>0</spring_stiffness>
        </dynamics>
      </axis>
    </joint>
  </model>
</sdf>
